<xacro:property name="dist_joint_offset" value="0.75" />
<xacro:property name="dist_joint_multiplier" value="0.3" />
<xacro:property name="spread_joint_offset" value="0" />
<xacro:property name="spread_joint_multiplier" value="1" />

<xacro:property name="PI" value="3.1415926535897931"/>
<xacro:property name="PI_2" value="1.570796327"/>
<xacro:property name="joint_damping" value="100.0" />
<xacro:property name="joint_friction" value="1.0" />
<xacro:property name="joint_effort_limit" value="60.0" />
<xacro:property name="joint_velocity_limit" value="2.0" />
<xacro:property name="mechanical_reduction" value="1.0" />
<xacro:macro name="bhand_macro" params="parent name *origin">

<!-- HAND BASE_LINK (RED) -->
<link name="${name}_base_link">
	<inertial>
		<mass value="1.0" />
		<origin xyz="0 0 0" />
		<inertia ixx="1.0" ixy="0.0" ixz="0.0" iyy="1.0" iyz="0.0" izz="1.0" />
	</inertial>
	<visual>
		<origin xyz="0 0 0" rpy="1.570796327 0 0" />
		<geometry>
			<mesh filename="package://bhand_description/meshes/palm_262.stl"/>
		</geometry>
		<material name="Gold">
			<color rgba="199 154 48 1.0"/>
		</material>
	</visual>
	<collision>
		<origin xyz="0 0 0" rpy= "0 0 0" />
		<geometry>
			<mesh filename="package://bhand_description/meshes/palm_262.stl"/>
		</geometry>
		<contact_coefficients kd="1.0" kp="1000.0" mu="0"/>
	</collision>
</link>

<joint name="${name}_base_joint" type="fixed">
	<insert_block name="origin"/>
	<parent link="${parent}"/>
	<child link="${name}_base_link"/>
</joint>

<!-- finger 3 -->
<!-- finger 31 link -->
<link name="${name}_finger_31_link">
	<inertial>
		<mass value="0.1"/>
		<origin xyz="0 0 0" rpy="0 0 0" />
		<inertia ixx="0.01" ixy="0" ixz="0" iyy="0.01" iyz="0" izz="0.01" />
	</inertial>
	<visual>
		<origin xyz="0 0 0" rpy="0 0 0" />
		<geometry>
			<mesh filename="package://bhand_description/meshes/knuckle_fixed.stl" />
		</geometry>
		<material name="Black" />
	</visual>
	<collision>
		<origin xyz="0 0 0" rpy="0 0 0" />
		<geometry>
		<mesh filename="package://bhand_description/meshes/knuckle_fixed.stl"/>
		</geometry>
		<contact_coefficients kd="1.0" kp="1000.0" mu="0"/>
	</collision>
</link>

<!-- joint between BH_palm_link and BH_finger_31_link -->
<!-- finger3 is the center finger and is fixed -->
<joint name="${name}_j31_joint" type="fixed" >
	<parent link="${name}_base_link" />
	<child link="${name}_finger_31_link" />
	<origin xyz="0 0.05 0.037" rpy="1.57079632679 0 0"/>
</joint>

<!-- finger 32 link -->
<link name="${name}_finger_32_link">
	<inertial>
		<mass value="0.1"/>
		<origin xyz=".5 0 0" rpy="0 1.57079632679 0"/>
		<inertia ixx="0.01" ixy="0" ixz="0" iyy="0.01" iyz="0" izz="0.01" />
	</inertial>
	<visual>
		<origin xyz="0 0 0" rpy="0 0 0" />
		<geometry>
		<mesh filename="package://bhand_description/meshes/finger.stl" />
		</geometry>
		<material name="Blue" />
	</visual>
	<collision>
		<origin xyz="0 0 0" rpy="0 0 0" />
		<geometry>
		<mesh filename="package://bhand_description/meshes/finger.stl" />
		</geometry>
		<contact_coefficients kd="1.0" kp="1000.0" mu="0" />
	</collision>
</link>

<!-- joint"between"BH_finger_31_link"and"BH_finger_32_link" -->
<joint name="${name}_j32_joint" type="revolute">
	<parent link="${name}_finger_31_link"/>
	<child link="${name}_finger_32_link"/>
	<origin xyz="0 0 0" rpy="3.1415 0 0"/>
	<axis xyz="1 0 0"/>
	<limit effort="${joint_effort_limit}" lower="0.0" upper="2.44" velocity="${joint_velocity_limit}" />
	<dynamics damping="${joint_damping}" friction="${joint_friction}" />
</joint>

<!-- finger 33 link -->
<link name="${name}_finger_33_link">
	<inertial>
		<mass value="0.1"/>
		<origin xyz="0 0 0" rpy="0 0 0" />
		<inertia ixx="0.01" ixy="0" ixz="0" iyy="0.01" iyz="0" izz="0.01" />
	</inertial>
	<visual>
		<origin xyz="0 0 0" rpy="0 0 0" />
		<geometry>
			<mesh filename="package://bhand_description/meshes/finger_tip.stl" />
		</geometry>
		<material name="Blue" />
	</visual>
	<collision>
		<origin xyz="0 0 0" rpy="0 0 0" />
		<geometry>
			<mesh filename="package://bhand_description/meshes/finger_tip.stl" />
		</geometry>
		<contact_coefficients kd="1.0" kp="1000.0" mu="0"/>
	</collision>
</link>

<!-- joint between BH_finger_32_link and BH_finger_33_link -->
<joint name= "${name}_j33_joint" type="revolute" >
	<parent link="${name}_finger_32_link" />
	<child link="${name}_finger_33_link" />
	<origin xyz="0 0 .07" rpy="0 0 0" />
	<axis xyz="1 0 0" />
	<limit effort="${joint_effort_limit}" lower="0.0" upper="0.84" velocity="${joint_velocity_limit}" />
	<dynamics damping="${joint_damping}" friction="${joint_friction}" />
	<mimic joint="${name}_j32_joint" multiplier="${dist_joint_multiplier}" offset="${dist_joint_offset}"/>
</joint>

<!-- fingerprint 3 link -->
<link name="${name}_fingerprint_3_link">
	<inertial>
		<mass value="0.1"/>
		<origin xyz="0 0 0" rpy="0 0 0"/>
		<inertia ixx="0.01" ixy="0" ixz="0" iyy="0.01" iyz="0" izz="0.01" />
	</inertial>
	<visual>
		<origin xyz="0 0 0" rpy="0 0 0"/>
		<geometry>
			<mesh filename="package://bhand_description/meshes/fingerprint.stl"/>""
		</geometry>""
		<material name="Black"/>
	</visual>
	<collision>
		<origin xyz="0 0 0" rpy="0 0 0" />
		<geometry>
			<mesh filename="package://bhand_description/meshes/fingerprint.stl"/>
		</geometry>
		<contact_coefficients kd="1.0" kp="1000.0" mu="0" />
	</collision>
</link>

<!-- joint between fingerprint_3 and finger_33_link -->
<joint name="${name}_fp3_joint" type="fixed" >
	<parent link="${name}_finger_33_link" />
	<child link="${name}_fingerprint_3_link"/>
	<origin xyz="0 0 0.04" rpy="0 3.14159265359 0" />
</joint>

<!-- finger 1 spread link -->
<link name="${name}_finger_1_spread_link">
	<inertial>
		<mass value="0.1"/>
		<origin xyz="0 0 0" rpy="0 0 0"/>
		<inertia ixx="0.01" ixy="0" ixz="0" iyy="0.01" iyz="0" izz="0.01" />
	</inertial>
	<visual>
		<origin xyz="0 0 0" rpy="0 0 0"/>
		<geometry>
			<mesh filename="package://bhand_description/meshes/knuckle.stl" />
		</geometry>
		<material name="Green" />
	</visual>
	<collision>
		<origin xyz="0 0 0" rpy="0 0 0" />
		<geometry>
			<mesh filename="package://bhand_description/meshes/knuckle.stl"/>
		</geometry>
	</collision>
</link>

<!-- joint between BH_palm_link and BH_finger_1_spread_link -->
<joint name="${name}_j1_spread_joint" type="revolute">
	<parent link="${name}_base_link"/>
	<child link="${name}_finger_1_spread_link"/>
	<origin xyz="-0.025 0 0.003" rpy="1.5708 0 0"/>
	<axis xyz="0 -1 0"/>
	<limit effort="${joint_effort_limit}" lower="0" upper="3.1416" velocity="${joint_velocity_limit}"/>
	<dynamics damping="${joint_damping}" friction="${joint_friction}"/>
</joint>

<joint name="${name}_j2_spread_joint" type="revolute">
	<parent link="${name}_base_link"/>
	<child link="${name}_finger_2_spread_link"/>
	<origin xyz="0.025 0 0.0035" rpy="1.5708 0 0"/>
	<axis xyz="0 1 0"/>
	<limit effort="${joint_effort_limit}" lower="0" upper="3.1416" velocity="${joint_velocity_limit}"/>
	<dynamics damping="${joint_damping}" friction="${joint_friction}"/>
	<mimic joint="${name}_j1_spread_joint" multiplier="${spread_joint_multiplier}" offset="${spread_joint_offset}"/>
</joint>

<!--joint between finger_1_spread and BH_finger_11_link -->
<joint name="${name}_j11_joint" type="fixed">
	<parent link="${name}_finger_1_spread_link"/>
	<child link="${name}_finger_11_link"/>
	<origin xyz="0 0.0337 0.050" rpy="0 3.1415 0" />
</joint>